Workbook

Sheet CEE
A1: COUNTRY | B1: CODE | C1: YEAR | D1: NOIP | E1: OFDIPC | F1: IFDIPC | G1: GNIPC | H1: IVA | I1: FVA | J1: GVCPAR | K1: GVCPOS | L1: TRO | M1: GDS | N1: REER | O1: IND | P1: GDPPC | Q1: EVA | R1: POP | S1: EVPC
A2: Czechia | B2: CZE | C2: 1995 | D2: -679.30566 | E2: 33.456168 | F2: 712.76183 | G2: 13850 | H2: 0.16827 | I2: 0.23722 | J2: 0.40549 | K2: -0.057342905 | L2: 82.900999 | M2: 30.812066 | N2: 62.53 | O2: 35.100532 | P2: 5874 | Q2: {=_xlfn.XLOOKUP(CEE!A2&CEE!C2,Sheet5!A:A&Sheet5!B:B,Sheet5!J:J,"")} -> 12539.313 | R2: {=_xlfn.XLOOKUP(B2&C2,Sheet6!B:B&Sheet6!C:C,Sheet6!D:D,"")} -> 10312 | S2: =Q2/R2*1000 -> 1215.9923
A3: Czechia | B3: CZE | C3: 1996 | D3: -784.18803 | E3: 48.368298 | F3: 832.55633 | G3: 14560 | H3: 0.17097 | I3: 0.22483 | J3: 0.3958 | K3: -0.044969594 | L3: 80.599558 | M3: 31.030569 | N3: 66.28 | O3: 35.885624 | P3: 6585 | Q3: {=_xlfn.XLOOKUP(CEE!A3&CEE!C3,Sheet5!A:A&Sheet5!B:B,Sheet5!J:J,"")} -> 13006.527 | R3: {=_xlfn.XLOOKUP(B3&C3,Sheet6!B:B&Sheet6!C:C,Sheet6!D:D,"")} -> 10296 | S3: =Q3/R3*1000 -> 1263.2602
A4: Czechia | B4: CZE | C4: 1997 | D4: -844.94163 | E4: 53.307393 | F4: 898.24903 | G4: 14690 | H4: 0.16612 | I4: 0.24543 | J4: 0.41155 | K4: -0.065798853 | L4: 84.153231 | M4: 28.57831 | N4: 66.7 | O4: 35.451465 | P4: 6084 | Q4: {=_xlfn.XLOOKUP(CEE!A4&CEE!C4,Sheet5!A:A&Sheet5!B:B,Sheet5!J:J,"")} -> 12914.744 | R4: {=_xlfn.XLOOKUP(B4&C4,Sheet6!B:B&Sheet6!C:C,Sheet6!D:D,"")} -> 10280 | S4: =Q4/R4*1000 -> 1256.2981
A5: Czechia | B5: CZE | C5: 1998 | D5: -1322.0653 | E5: 78.324403 | F5: 1400.3897 | G5: 14840 | H5: 0.16735 | I5: 0.24662 | J5: 0.41397 | K5: -0.065699666 | L5: 83.938652 | M5: 30.432149 | N5: 73.44 | O5: 34.566763 | P5: 6545 | Q5: {=_xlfn.XLOOKUP(CEE!A5&CEE!C5,Sheet5!A:A&Sheet5!B:B,Sheet5!J:J,"")} -> 14658.619 | R5: {=_xlfn.XLOOKUP(B5&C5,Sheet6!B:B&Sheet6!C:C,Sheet6!D:D,"")} -> 10265 | S5: =Q5/R5*1000 -> 1428.0194
A6: Czechia | B6: CZE | C6: 1999 | D6: -1644.1323 | E6: 68.090918 | F6: 1712.2232 | G6: 15210 | H6: 0.1714 | I6: 0.25602 | J6: 0.42742 | K6: -0.069748377 | L6: 85.457124 | M6: 29.269586 | N6: 72.04 | O6: 33.561169 | P6: 6398 | Q6: {=_xlfn.XLOOKUP(CEE!A6&CEE!C6,Sheet5!A:A&Sheet5!B:B,Sheet5!J:J,"")} -> 14421.904 | R6: {=_xlfn.XLOOKUP(B6&C6,Sheet6!B:B&Sheet6!C:C,Sheet6!D:D,"")} -> 10251 | S6: =Q6/R6*1000 -> 1406.8778
A7: Czechia | B7: CZE | C7: 2000 | D7: -2042.1999 | E7: 72.091433 | F7: 2114.2913 | G7: 16020 | H7: 0.1858 | I7: 0.2858 | J7: 0.4716 | K7: -0.08096344 | L7: 97.498396 | M7: 29.981081 | N7: 72.64 | O7: 33.305413 | P7: 6073 | Q7: {=_xlfn.XLOOKUP(CEE!A7&CEE!C7,Sheet5!A:A&Sheet5!B:B,Sheet5!J:J,"")} -> 15660.253 | R7: {=_xlfn.XLOOKUP(B7&C7,Sheet6!B:B&Sheet6!C:C,Sheet6!D:D,"")} -> 10237 | S7: =Q7/R7*1000 -> 1529.7698
A8: Czechia | B8: CZE | C8: 2001 | D8: -2536.7475 | E8: 111.02424 | F8: 2647.7717 | G8: 17210 | H8: 0.18523 | I8: 0.28887 | J8: 0.4741 | K8: -0.083829017 | L8: 98.536874 | M8: 30.712841 | N8: 77.53 | O8: 33.740653 | P8: 6659 | Q8: {=_xlfn.XLOOKUP(CEE!A8&CEE!C8,Sheet5!A:A&Sheet5!B:B,Sheet5!J:J,"")} -> 17547.038 | R8: {=_xlfn.XLOOKUP(B8&C8,Sheet6!B:B&Sheet6!C:C,Sheet6!D:D,"")} -> 10232 | S8: =Q8/R8*1000 -> 1714.9177
A9: Czechia | B9: CZE | C9: 2002 | D9: -3632.7766 | E9: 143.86171 | F9: 3776.6383 | G9: 17690 | H9: 0.18979 | I9: 0.28549 | J9: 0.47528 | K9: -0.077363148 | L9: 90.879272 | M9: 29.161838 | N9: 86.94 | O9: 33.061018 | P9: 8068 | Q9: {=_xlfn.XLOOKUP(CEE!A9&CEE!C9,Sheet5!A:A&Sheet5!B:B,Sheet5!J:J,"")} -> 19518.879 | R9: {=_xlfn.XLOOKUP(B9&C9,Sheet6!B:B&Sheet6!C:C,Sheet6!D:D,"")} -> 10239 | S9: =Q9/R9*1000 -> 1906.3267
A10: Czechia | B10: CZE | C10: 2003 | D10: -4195.824 | E10: 222.85101 | F10: 4418.675 | G10: 18950 | H10: 0.1897 | I10: 0.3118 | J10: 0.5015 | K10: -0.097699065 | L10: 94.64686 | M10: 28.037373 | N10: 86.08 | O10: 32.210044 | P10: 9800 | Q10: {=_xlfn.XLOOKUP(CEE!A10&CEE!C10,Sheet5!A:A&Sheet5!B:B,Sheet5!J:J,"")} -> 25395.906 | R10: {=_xlfn.XLOOKUP(B10&C10,Sheet6!B:B&Sheet6!C:C,Sheet6!D:D,"")} -> 10249 | S10: =Q10/R10*1000 -> 2477.8911
A11: Czechia | B11: CZE | C11: 2004 | D11: -5213.8193 | E11: 366.43602 | F11: 5580.2553 | G11: 20000 | H11: 0.18691 | I11: 0.34886 | J11: 0.53577 | K11: -0.1279065 | L11: 113.17398 | M11: 30.449252 | N11: 87.33 | O11: 33.452416 | P11: 11709 | Q11: {=_xlfn.XLOOKUP(CEE!A11&CEE!C11,Sheet5!A:A&Sheet5!B:B,Sheet5!J:J,"")} -> 37852.081 | R11: {=_xlfn.XLOOKUP(B11&C11,Sheet6!B:B&Sheet6!C:C,Sheet6!D:D,"")} -> 10261 | S11: =Q11/R11*1000 -> 3688.9271
A12: Czechia | B12: CZE | C12: 2005 | D12: -5549.8054 | E12: 351.16732 | F12: 5900.9728 | G12: 21090 | H12: 0.18347 | I12: 0.36619 | J12: 0.54966 | K12: -0.14357504 | L12: 121.19129 | M12: 31.612048 | N12: 92.14 | O12: 33.531742 | P12: 13352 | Q12: {=_xlfn.XLOOKUP(CEE!A12&CEE!C12,Sheet5!A:A&Sheet5!B:B,Sheet5!J:J,"")} -> 46894.422 | R12: {=_xlfn.XLOOKUP(B12&C12,Sheet6!B:B&Sheet6!C:C,Sheet6!D:D,"")} -> 10280 | S12: =Q12/R12*1000 -> 4561.7142
A13: Czechia | B13: CZE | C13: 2006 | D13: -7260.9413 | E13: 486.85104 | F13: 7747.7923 | G13: 22430 | H13: 0.18785 | I13: 0.37594 | J13: 0.56379 | K13: -0.14699218 | L13: 127.05102 | M13: 32.802644 | N13: 96.83 | O13: 34.276816 | P13: 15162 | Q13: {=_xlfn.XLOOKUP(CEE!A13&CEE!C13,Sheet5!A:A&Sheet5!B:B,Sheet5!J:J,"")} -> 57444.471 | R13: {=_xlfn.XLOOKUP(B13&C13,Sheet6!B:B&Sheet6!C:C,Sheet6!D:D,"")} -> 10305 | S13: =Q13/R13*1000 -> 5574.4271
... A365: Ukraine | B365: UKR | C365: 2022 | D365: -1263.222 | E365: -21.121099 | F365: 1242.1009 | G365: 15540 | H365: 0.24581 | I365: 0.29941 | J365: 0.54522 | K365: -0.042124395 | L365: 87.396514 | M365: -4.3929947 | N365: 83.96 | O365: 18.010832 | P365: 3946 | Q365: {=_xlfn.XLOOKUP(CEE!A365&CEE!C365,Sheet5!A:A&Sheet5!B:B,Sheet5!J:J,"")} -> 28426.74 | R365: {=_xlfn.XLOOKUP(B365&C365,Sheet6!B:B&Sheet6!C:C,Sheet6!D:D,"")} -> 41049 | S365: =Q365/R365*1000 -> 692.50749

Sheet Sheet6
A1: COUNTRY | B1: CODE | C1: YEAR | D1: POP
A2: Afghanistan | B2: AFG | C2: 1990 | D2: 12046
A3: Afghanistan | B3: AFG | C3: 1991 | D3: 12239
A4: Afghanistan | B4: AFG | C4: 1992 | D4: 13279
A5: Afghanistan | B5: AFG | C5: 1993 | D5: 14943
A6: Afghanistan | B6: AFG | C6: 1994 | D6: 16251
A7: Afghanistan | B7: AFG | C7: 1995 | D7: 17066
A8: Afghanistan | B8: AFG | C8: 1996 | D8: 17763
A9: Afghanistan | B9: AFG | C9: 1997 | D9: 18452
A10: Afghanistan | B10: AFG | C10: 1998 | D10: 19160
A11: Afghanistan | B11: AFG | C11: 1999 | D11: 19888
A12: Afghanistan | B12: AFG | C12: 2000 | D12: 20130
A13: Afghanistan | B13: AFG | C13: 2001 | D13: 20284
... A7196: Zimbabwe | B7196: ZWE | C7196: 2025 | D7196: 16951

Sheet Sheet4
A1: Economy_Label | B1: Custom | C1: Value
A2: Individual economies | B2: 1970
A3: Individual economies | B3: 1971
A4: Individual economies | B4: 1972
A5: Individual economies | B5: 1973
A6: Individual economies | B6: 1974
A7: Individual economies | B7: 1975
A8: Individual economies | B8: 1976
A9: Individual economies | B9: 1977
A10: Individual economies | B10: 1978
A11: Individual economies | B11: 1979
A12: Individual economies | B12: 1980
A13: Individual economies | B13: 1981
... A57: Individual economies | B57: 2025
A58: Afghanistan | B58: 1970 | C58: 155
A59: Afghanistan | B59: 1971 | C59: 158
A60: Afghanistan | B60: 1972 | C60: 135
A61: Afghanistan | B61: 1973 | C61: 143
A62: Afghanistan | B62: 1974 | C62: 173
A63: Afghanistan | B63: 1975 | C63: 185
A64: Afghanistan | B64: 1976 | C64: 196
A65: Afghanistan | B65: 1977 | C65: 221
A66: Afghanistan | B66: 1978 | C66: 242
A67: Afghanistan | B67: 1979 | C67: 271
A68: Afghanistan | B68: 1980 | C68: 277
A69: Afghanistan | B69: 1981 | C69: 291
... A505: Argentina | B505: 2025 | C505: 14903
A506: Armenia | B506: 1970
A507: Armenia | B507: 1971
A508: Armenia | B508: 1972
A509: Armenia | B509: 1973
A510: Armenia | B510: 1974
A511: Armenia | B511: 1975
A512: Armenia | B512: 1976
A513: Armenia | B513: 1977
A514: Armenia | B514: 1978
A515: Armenia | B515: 1979
A516: Armenia | B516: 1980
A517: Armenia | B517: 1981
... A527: Armenia | B527: 1991
...

Sheet Sheet5
A1: COUNTRY | B1: YEAR | C1: IV | D1: FV | E1: EXP | F1: IVA | G1: FVA | H1: GVCPAR | I1: GVCPOS | J1: EVA
A2: Australia | B2: 1995 | C2: 26640.203 | D2: 7073.465 | E2: 65484.076 | F2: =C2/$E2 -> 0.40681956 | G2: =D2/$E2 -> 0.10801809 | H2: =F2+G2 -> 0.51483765 | I2: =LN((1+F2)/(1+G2)) -> 0.23875861 | J2: =C2+D2 -> 33713.668
A3: Australia | B3: 1996 | C3: 31282.725 | D3: 8271.427 | E3: 75443.611 | F3: =C3/$E3 -> 0.41465042 | G3: =D3/$E3 -> 0.10963721 | H3: =F3+G3 -> 0.52428763 | I3: =LN((1+F3)/(1+G3)) -> 0.24284932 | J3: =C3+D3 -> 39554.152
A4: Australia | B4: 1997 | C4: 31631.903 | D4: 8612.879 | E4: 77100.578 | F4: =C4/$E4 -> 0.41026804 | G4: =D4/$E4 -> 0.11170966 | H4: =F4+G4 -> 0.5219777 | I4: =LN((1+F4)/(1+G4)) -> 0.23788072 | J4: =C4+D4 -> 40244.782
A5: Australia | B5: 1998 | C5: 27274.08 | D5: 8239.132 | E5: 67932.344 | F5: =C5/$E5 -> 0.40148887 | G5: =D5/$E5 -> 0.12128438 | H5: =F5+G5 -> 0.52277325 | I5: =LN((1+F5)/(1+G5)) -> 0.22306036 | J5: =C5+D5 -> 35513.212
A6: Australia | B6: 1999 | C6: 29892.151 | D6: 8911.124 | E6: 72191.874 | F6: =C6/$E6 -> 0.41406531 | G6: =D6/$E6 -> 0.12343666 | H6: =F6+G6 -> 0.53750198 | I6: =LN((1+F6)/(1+G6)) -> 0.23007632 | J6: =C6+D6 -> 38803.275
A7: Australia | B7: 2000 | C7: 31028.527 | D7: 9214.255 | E7: 75285.576 | F7: =C7/$E7 -> 0.41214438 | G7: =D7/$E7 -> 0.12239071 | H7: =F7+G7 -> 0.53453509 | I7: =LN((1+F7)/(1+G7)) -> 0.22964841 | J7: =C7+D7 -> 40242.782
A8: Australia | B8: 2001 | C8: 30345.697 | D8: 8599.786 | E8: 73184.51 | F8: =C8/$E8 -> 0.41464645 | G8: =D8/$E8 -> 0.11750828 | H8: =F8+G8 -> 0.53215473 | I8: =LN((1+F8)/(1+G8)) -> 0.23577818 | J8: =C8+D8 -> 38945.483
A9: Australia | B9: 2002 | C9: 30335.373 | D9: 8468.346 | E9: 73946.758 | F9: =C9/$E9 -> 0.41023263 | G9: =D9/$E9 -> 0.1145195 | H9: =F9+G9 -> 0.52475213 | I9: =LN((1+F9)/(1+G9)) -> 0.2353313 | J9: =C9+D9 -> 38803.719
A10: Australia | B10: 2003 | C10: 35324.75 | D10: 9957.975 | E10: 86105.012 | F10: =C10/$E10 -> 0.41025196 | G10: =D10/$E10 -> 0.11564919 | H10: =F10+G10 -> 0.52590115 | I10: =LN((1+F10)/(1+G10)) -> 0.23433191 | J10: =C10+D10 -> 45282.725
A11: Australia | B11: 2004 | C11: 44177.164 | D11: 11438.447 | E11: 105673.23 | F11: =C11/$E11 -> 0.41805445 | G11: =D11/$E11 -> 0.10824356 | H11: =F11+G11 -> 0.52629802 | I11: =LN((1+F11)/(1+G11)) -> 0.24650944 | J11: =C11+D11 -> 55615.611
A12: Australia | B12: 2005 | C12: 51261.48 | D12: 13816.902 | E12: 129152.94 | F12: =C12/$E12 -> 0.39690526 | G12: =D12/$E12 -> 0.10698093 | H12: =F12+G12 -> 0.50388619 | I12: =LN((1+F12)/(1+G12)) -> 0.23262283 | J12: =C12+D12 -> 65078.382
A13: Australia | B13: 2006 | C13: 57572.188 | D13: 16154.77 | E13: 144818.12 | F13: =C13/$E13 -> 0.39754823 | G13: =D13/$E13 -> 0.11155213 | H13: =F13+G13 -> 0.50910037 | I13: =LN((1+F13)/(1+G13)) -> 0.22896209 | J13: =C13+D13 -> 73726.958
... A2717: Other countries | B2717: 2022 | C2717: 851003.48 | D2717: 367983.44 | E2717: 3158050.8 | F2717: =C2717/$E2717 -> 0.26947112 | G2717: =D2717/$E2717 -> 0.11652233 | H2717: =F2717+G2717 -> 0.38599345 | I2717: =LN((1+F2717)/(1+G2717)) -> 0.12838158 | J2717: =C2717+D2717 -> 1218986.9

Sheet Sheet3
A1: Entity | B1: Code | C1: Year | D1: Gross national income per capita | E1: Column1
A2: Afghanistan | B2: AFG | C2: 1990 | D2: 3642.0496
A3: Afghanistan | B3: AFG | C3: 1991 | D3: 3192,8137
A4: Afghanistan | B4: AFG | C4: 1992 | D4: 2990,1565
A5: Afghanistan | B5: AFG | C5: 1993 | D5: 1993,698
A6: Afghanistan | B6: AFG | C6: 1994 | D6: 1425,204
A7: Afghanistan | B7: AFG | C7: 1995 | D7: 2034,991
A8: Afghanistan | B8: AFG | C8: 1996 | D8: 1852,2079
A9: Afghanistan | B9: AFG | C9: 1997 | D9: 1690,9052
A10: Afghanistan | B10: AFG | C10: 1998 | D10: 1554,304
A11: Afghanistan | B11: AFG | C11: 1999 | D11: 1425,3145
A12: Afghanistan | B12: AFG | C12: 2000 | D12: 1331,14
A13: Afghanistan | B13: AFG | C13: 2001 | D13: 1246,1584
A14: Afghanistan | B14: AFG | C14: 2002 | D14: 1946,6959
... A43: Africa | B43: OWID_AFR | C43: 1997 | D43: 3878,4934
A44: Africa | B44: OWID_AFR | C44: 1998 | D44: 3923.7842
A45: Africa | B45: OWID_AFR | C45: 1999 | D45: 3918.6326
A46: Africa | B46: OWID_AFR | C46: 2000 | D46: 3961,7766
A47: Africa | B47: OWID_AFR | C47: 2001 | D47: 4035,214
A48: Africa | B48: OWID_AFR | C48: 2002 | D48: 4146,606
A49: Africa | B49: OWID_AFR | C49: 2003 | D49: 4242,209
A50: Africa | B50: OWID_AFR | C50: 2004 | D50: 4375,582
A51: Africa | B51: OWID_AFR | C51: 2005 | D51: 4508,0835
A52: Africa | B52: OWID_AFR | C52: 2006 | D52: 4698,8223
A53: Africa | B53: OWID_AFR | C53: 2007 | D53: 4829,7563
A54: Africa | B54: OWID_AFR | C54: 2008 | D54: 5049,807
A55: Africa | B55: OWID_AFR | C55: 2009 | D55: 5102,392
A56: Africa | B56: OWID_AFR | C56: 2010 | D56: 5266,384
A57: Africa | B57: OWID_AFR | C57: 2011 | D57: 5251,615
... A239: Antigua and Barbuda | B239: ATG | C239: 2023 | D239: 27386,518
A240: Arab States (UNDP) | C240: 1990 | D240: 11043,375
A241: Arab States (UNDP) | C241: 1991 | D241: 10590,84
A242: Arab States (UNDP) | C242: 1992 | D242: 11012,955
A243: Arab States (UNDP) | C243: 1993 | D243: 11147,803
A244: Arab States (UNDP) | C244: 1994 | D244: 11213,888
A245: Arab States (UNDP) | C245: 1995 | D245: 11260,819
A246: Arab States (UNDP) | C246: 1996 | D246: 11724,73
A247: Arab States (UNDP) | C247: 1997 | D247: 12078,551
A248: Arab States (UNDP) | C248: 1998 | D248: 12563,469
A249: Arab States (UNDP) | C249: 1999 | D249: 12596,925
...

Sheet DEV
A1: COUNTRY | B1: CODE | C1: YEAR | D1: NOIP | E1: OFDIPC | F1: IFDIPC | G1: GNIPC | H1: IVA | I1: FVA | J1: GVCPAR | K1: GVCPOS | L1: TRO | M1: GDS | N1: REER | O1: IND
A2: Austria | B2: AUT | C2: 1995 | D2: -956.10063 | E2: 1433.9623 | F2: 2390.0629 | G2: 23510 | H2: 0.28144948 | I2: 0.18982835 | J2: 0.47127783 | K2: 0.074182791 | L2: 68.525006 | M2: 25.71068 | N2: 108.41574 | O2: 29.261908
A3: Austria | B3: AUT | C3: 1996 | D3: -823.01218 | E3: 1636.3522 | F3: 2459.3644 | G3: 24410 | H3: 0.26985018 | I3: 0.20177088 | J3: 0.47162107 | K3: 0.055102723 | L3: 70.469316 | M3: 25.064781 | N3: 104.74571 | O3: 29.130128
A4: Austria | B4: AUT | C4: 1997 | D4: -700.87829 | E4: 1782.1832 | F4: 2483.0615 | G4: 25180 | H4: 0.2694185 | I4: 0.21001403 | J4: 0.47943253 | K4: 0.047926967 | L4: 75.244476 | M4: 25.856146 | N4: 99.306663 | O4: 28.964856
A5: Austria | B5: AUT | C5: 1998 | D5: -761.09301 | E5: 2180.8724 | F5: 2941.9654 | G5: 26370 | H5: 0.26694108 | I5: 0.21474073 | J5: 0.4816818 | K5: 0.042074736 | L5: 77.349522 | M5: 26.319008 | N5: 99.998211 | O5: 28.834967
A6: Austria | B6: AUT | C6: 1999 | D6: -543.40756 | E6: 2392.6695 | F6: 2936.0771 | G6: 27060 | H6: 0.26829029 | I6: 0.21246996 | J6: 0.48076025 | K6: 0.045010203 | L6: 78.562933 | M6: 26.852404 | N6: 98.373286 | O6: 28.761833
A7: Austria | B7: AUT | C7: 2000 | D7: -791.71347 | E7: 3097.5914 | F7: 3889.3049 | G7: 28970 | H7: 0.25813944 | I7: 0.23258684 | J7: 0.49072628 | K7: 0.020518912 | L7: 85.842608 | M7: 27.103846 | N7: 93.958998 | O7: 28.611552
A8: Austria | B8: AUT | C8: 2001 | D8: -806.76449 | E8: 3545.2624 | F8: 4352.0269 | G8: 29150 | H8: 0.2580348 | I8: 0.2344942 | J8: 0.492529 | K8: 0.018889488 | L8: 87.996257 | M8: 27.023292 | N8: 94.123554 | O8: 28.439892
A9: Austria | B9: AUT | C9: 2002 | D9: -298.19352 | E9: 5256.7434 | F9: 5554.9369 | G9: 30770 | H9: 0.26193074 | I9: 0.22876396 | J9: 0.4906947 | K9: 0.026634125 | L9: 87.584494 | M9: 27.779984 | N9: 95.41146 | O9: 27.668343
A10: Austria | B10: AUT | C10: 2003 | D10: -206.2046 | E10: 6889.2035 | F10: 7095.4081 | G10: 31880 | H10: 0.26308668 | I10: 0.22762878 | J10: 0.49071547 | K10: 0.028473982 | L10: 86.882226 | M10: 26.958225 | N10: 99.234503 | O10: 27.697936
A11: Austria | B11: AUT | C11: 2004 | D11: -111.09752 | E11: 8541.0498 | F11: 8652.1473 | G11: 33470 | H11: 0.26177586 | I11: 0.24753499 | J11: 0.50931085 | K11: 0.011350546 | L11: 91.47422 | M11: 27.291707 | N11: 100.55445 | O11: 27.614789
A12: Austria | B12: AUT | C12: 2005 | D12: -1305.6264 | E12: 8726.0907 | F12: 10031.717 | G12: 34700 | H12: 0.25859832 | I12: 0.25563526 | J12: 0.51423357 | K12: 0.0023570283 | L12: 94.674755 | M12: 26.995432 | N12: 99.521411 | O12: 27.418205
A13: Austria | B13: AUT | C13: 2006 | D13: -481.01572 | E13: 12705.2 | F13: 13186.215 | G13: 37480 | H13: 0.25499677 | I13: 0.26599625 | J13: 0.52099303 | K13: -0.0087263623 | L13: 98.785725 | M13: 27.694752 | N13: 98.932606 | O13: 27.590907
... A393: Switzerland | B393: CHE | C393: 2022 | D393: 32246.474 | E393: 147132.51 | F393: 114886.03 | G393: 91180 | H393: 0.273865 | I393: 0.26006638 | J393: 0.53393137 | K393: 0.010891182 | L393: 136.23587 | M393: 40.353348 | N393: 121.77082 | O393: 25.974644
A394: Turkiye | B394: TUR | C394: 1995 | D394: -221.46661 | E394: 23.236379 | F394: 244.70299 | G394: 9820 | H394: 0.25344864 | I394: 0.091445269 | J394: 0.34489391 | K394: 0.13839591 | L394: 35.99248 | M394: 28.057548 | O394: 34.077781
A395: Turkiye | B395: TUR | C395: 1996 | D395: -228.03506 | E395: 24.664654 | F395: 252.69971 | G395: 10500 | H395: 0.26443058 | I395: 0.10675504 | J395: 0.37118561 | K395: 0.13318954 | L395: 39.647718 | M395: 28.55462 | O395: 33.255943
A396: Turkiye | B396: TUR | C396: 1997 | D396: -233.57676 | E396: 28.304138 | F396: 261.8809 | G396: 11380 | H396: 0.25244343 | I396: 0.10838427 | J396: 0.3608277 | K396: 0.12219305 | L396: 42.761067 | M396: 27.14499 | O396: 33.222473
A397: Turkiye | B397: TUR | C397: 1998 | D397: -239.3385 | E397: 33.671196 | F397: 273.0097 | G397: 8670 | H397: 0.26906789 | I397: 0.093132048 | J397: 0.36219994 | K397: 0.14923567 | L397: 40.376989 | M397: 26.231739 | O397: 31.017772
A398: Turkiye | B398: TUR | C398: 1999 | D398: -238.29576 | E398: 43.209685 | F398: 281.50545 | G398: 8350 | H398: 0.27628607 | I398: 0.10796977 | J398: 0.38425583 | K398: 0.14142505 | L398: 37.666504 | M398: 21.499975 | O398: 28.282859
A399: Turkiye | B399: TUR | C399: 2000 | D399: -231.46761 | E399: 56.063339 | F399: 287.53095 | G399: 9190 | H399: 0.26458014 | I399: 0.12920645 | J399: 0.39378659 | K399: 0.11322503 | L399: 42.374675 | M399: 21.503476 | O399: 26.803868
A400: Turkiye | B400: TUR | C400: 2001 | D400: -237.52736 | E400: 69.152389 | F400: 306.67975 | G400: 8790 | H400: 0.29015463 | I400: 0.1447396 | J400: 0.43489423 | K400: 0.11958489 | L400: 49.944783 | M400: 24.263699 | O400: 25.521851
A401: Turkiye | B401: TUR | C401: 2002 | D401: -193.57485 | E401: 87.20488 | F401: 280.77973 | G401: 8980 | H401: 0.31834876 | I401: 0.16025069 | J401: 0.47859945 | K401: 0.12774392 | L401: 48.10261 | M401: 23.953632 | O401: 24.631867
A402: Turkiye | B402: TUR | C402: 2003 | D402: -399.53119 | E402: 90.488265 | F402: 490.01946 | G402: 9310 | H402: 0.31890065 | I402: 0.16583819 | J402: 0.48473884 | K402: 0.12335824 | L402: 46.368155 | M402: 22.877947 | O402: 24.843293
A403: Turkiye | B403: TUR | C403: 2004 | D403: -460.2802 | E403: 102.92595 | F403: 563.20616 | G403: 10610 | H403: 0.31118411 | I403: 0.17702096 | J403: 0.48820507 | K403: 0.10794399 | L403: 48.993458 | M403: 23.883193 | O403: 25.159228
A404: Turkiye | B404: TUR | C404: 2005 | D404: -910.34184 | E404: 119.93365 | F404: 1030.2755 | G404: 11680 | H404: 0.31725362 | I404: 0.1789423 | J404: 0.49619592 | K404: 0.1109313 | L404: 46.308831 | M404: 25.496236 | O404: 25.294144
A405: Turkiye | B405: TUR | C405: 2006 | D405: -1236.4337 | E405: 126.57577 | F405: 1363.0095 | G405: 13410 | H405: 0.30360085 | I405: 0.19616419 | J405: 0.49976504 | K405: 0.086010394 | L405: 48.945677 | M405: 26.563409 | O405: 26.094974
... A421: Turkiye | B421: TUR | C421: 2022 | D421: -2351.2371 | E421: 616.49705 | F421: 2967.7342 | G421: 39520 | H421: 0.24217739 | I421: 0.27332647 | J421: 0.51550386 | K421: -0.024766944 | L421: 79.898272 | M421: 34.986289 | O421: 30.890102
A422: United Kingdom | B422: GBR | C422: 1995 | D422: 1807.1189 | E422: 5242.2836 | F422: 3435.1646 | G422: 20080 | H422: 0.32173843 | I422: 0.15118184 | J422: 0.47292027 | K422: 0.13815876 | L422: 50.830077 | M422: 19.483906 | N422: 83.30746 | O422: 24.453721
A423: United Kingdom | B423: GBR | C423: 1996 | D423: 1745.9991 | E423: 5667.9017 | F423: 3921.9026 | G423: 21340 | H423: 0.32151407 | I423: 0.15373987 | J423: 0.47525395 | K423: 0.13576938 | L423: 52.057609 | M423: 19.602149 | N423: 83.842188 | O423: 24.582836
A424: United Kingdom | B424: GBR | C424: 1997 | D424: 1845.0391 | E424: 6173.0457 | F424: 4328.0066 | G424: 22810 | H424: 0.33074788 | I424: 0.14590445 | J424: 0.47665233 | K424: 0.14954687 | L424: 50.704562 | M424: 18.831054 | N424: 95.716972 | O424: 23.716719
A425: United Kingdom | B425: GBR | C425: 1998 | D425: 2575.3663 | E425: 8330.155 | F425: 5754.7887 | G425: 23900 | H425: 0.34054016 | I425: 0.13896839 | J425: 0.47950855 | K425: 0.1629497 | L425: 49.140909 | M425: 18.300585 | N425: 100.98857 | O425: 23.065624
A426: United Kingdom | B426: GBR | C426: 1999 | D426: 5120.3114 | E426: 11666.072 | F426: 6545.7605 | G426: 24490 | H426: 0.3370751 | I426: 0.13932812 | J426: 0.47640322 | K426: 0.16004575 | L426: 49.468391 | M426: 17.49138 | N426: 100.71142 | O426: 22.566151
A427: United Kingdom | B427: GBR | C427: 2000 | D427: 8478.9102 | E427: 15920.162 | F427: 7441.2517 | G427: 26710 | H427: 0.32673248 | I427: 0.14206003 | J427: 0.46879251 | K427: 0.14988546 | L427: 52.338021 | M427: 17.721603 | N427: 100.69098 | O427: 22.680965
A428: United Kingdom | B428: GBR | C428: 2001 | D428: 7163.0853 | E428: 15253.778 | F428: 8090.6929 | G428: 28170 | H428: 0.32216216 | I428: 0.14665498 | J428: 0.46881714 | K428: 0.1424194 | L428: 52.634237 | M428: 17.060655 | N428: 98.272228 | O428: 21.773303
A429: United Kingdom | B429: GBR | C429: 2002 | D429: 9236.6772 | E429: 17493.106 | F429: 8256.4283 | G429: 29500 | H429: 0.32099743 | I429: 0.1434427 | J429: 0.46444012 | K429: 0.14434345 | L429: 51.236182 | M429: 16.326008 | N429: 99.177902 | O429: 21.237002
A430: United Kingdom | B430: GBR | C430: 2003 | D430: 11247.392 | E430: 20785.941 | F430: 9538.549 | G430: 30760 | H430: 0.31935732 | I430: 0.13980122 | J430: 0.45915854 | K430: 0.14629086 | L430: 50.068119 | M430: 16.191578 | N430: 95.443283 | O430: 20.876086
A431: United Kingdom | B431: GBR | C431: 2004 | D431: 11142.347 | E431: 22108.06 | F431: 10965.714 | G431: 32420 | H431: 0.31484485 | I431: 0.14273761 | J431: 0.45758246 | K431: 0.14029188 | L431: 50.288552 | M431: 15.781118 | N431: 99.379887 | O431: 20.219826
A432: United Kingdom | B432: GBR | C432: 2005 | D432: 7445.1449 | E432: 20451.779 | F432: 13006.634 | G432: 33170 | H432: 0.3111083 | I432: 0.1514308 | J432: 0.4625391 | K432: 0.12986747 | L432: 52.544274 | M432: 16.282998 | N432: 97.458 | O432: 20.264543
A433: United Kingdom | B433: GBR | C433: 2006 | D433: 7005.0941 | E433: 23961.508 | F433: 16956.413 | G433: 34730 | H433: 0.29942353 | I433: 0.16495169 | J433: 0.46437522 | K433: 0.10924111 | L433: 56.704779 | M433: 17.030607 | N433: 97.786835 | O433: 20.194644
... A477: Russia | B477: RUS | C477: 2022 | D477: -417.99011 | E477: 2054.7534 | F477: 2472.7435 | G477: 40090 | H477: 0.35540148 | I477: 0.075098257 | J477: 0.43049973 | K477: 0.23168564 | L477: 42.766308 | M477: 35.826175 | N477: 103.25215 | O477: 32.198122
